Workbook

Sheet Données à saisir
A1: Saisissez dans cet onglet toutes les données de votre projet
A2: Le plan financier apparaitra dans l'onglet suivant
N3: Impôt sur le revenu
A4: Renseignez les cases Grises uniquement : | N4: Impôt sur les sociétés
A6: Votre prénom et nom : | B6: Gracy Omokoso
A7: Votre projet : | B7: Televerx | D7: Nom de votre projet ou description de votre activité
A8: Votre statut juridique : | D8: Par exemple : SARL, Entreprise individuelle…
A9: Votre numéro de téléphone : | B9: +243896120025
A10: Votre adresse e-mail : | B10: contact@caftret.com
A11: Votre ville ou commune d'activité : | B11: Kinshasa
A12: Votre devise : | B12: USD | D12: Par exemple : Euro, franc CFA…
A13: Taux d'impôt sur les sociétés : | B13: 0 | C13: Saisir obligatoirement un pourcentage
A14: 1) Vos besoins de démarrage :
A15: Listez toutes les dépenses ou investissements que vous devrez faire avant même de démarrer l’activité, en hors taxes (ou TTC si vous n'êtes pas soumis à la TVA)
B16: Montant
A17: Frais d’établissement | C17: Ce sont les frais de création de l’entreprise (formalités)
A18: Frais d’ouverture de compteurs | C18: Compteurs d'eau, électricité, gaz…
A19: Logiciels, formations
A20: Dépôt marque, brevet, modèle | B20: 500 | C20: Frais de dépôt ou d’enregistrement
A21: Droits d’entrée | C21: Par exemple pour intégrer un réseau de franchise
A22: Achat fonds de commerce ou parts | C22: Dans le cas d'une reprise
A23: Droit au bail | B23: 750
A24: Caution ou dépôt de garantie
A25: Frais de dossier | C25: Pour la signature de contrats de prêt
A26: Frais de notaire ou d’avocat | C26: Pour la signature des contrats et baux commerciaux
A27: Enseigne et éléments de communication | B27: 4200 | C27: Cartes de visite, brochures, logo, site internet, éléments graphiques
A28: Achat immobilier | C28: Acquisition d'immeuble
A29: Travaux et aménagements | C29: Pour l'aménagement du local
A30: Matériel | B30: 7200 | C30: Ordinateurs, Véhicule, Moto
A31: Matériel de bureau | C31: Fournitures, ordinateur, imprimante
A32: Stock de matières et produits | C32: Matières premières, produits finis ou semi-finis
A33: Trésorerie de départ | B33: 8000 | C33: Somme d’argent gardée en prévision du démarrage de l’activité pour financer le cycle d'exploitation
A34: TOTAL | B34: =SUM(B17:B33) -> 20650
A36: Durée d'amortissement des investissements : | C36: 5 | D36: (obligatoire ; durée de vie des acquisitions de départ, en années)
B38: Montant à amortir | C38: Année 1 | D38: Année 2 | E38: Année 3 | F38: Année 4 | G38: Année 5 | H38: Année 6 | I38: Année 7 | J38: Année 8 | K38: Année 9 | L38: Année 10 | M38: TOTAL
B39: =SUM(B17,B19,B21,B25:B31) -> 11400 | C39: =IF(ISERROR($B39/$C$36),0,$B39/$C$36) -> 2280 | D39: =IF($B39>(SUM($C39:C39)),IF(ISERROR($B39/$C$36),"",$B39/$C$36),0) -> 2280 | E39: =IF($B39>(SUM($C39:D39)),IF(ISERROR($B39/$C$36),"",$B39/$C$36),0) -> 2280 | F39: =IF($B39>(SUM($C39:E39)),IF(ISERROR($B39/$C$36),"",$B39/$C$36),0) -> 2280 | G39: =IF($B39>(SUM($C39:F39)),IF(ISERROR($B39/$C$36),"",$B39/$C$36),0) -> 2280 | H39: =IF($B39>(SUM($C39:G39)),IF(ISERROR($B39/$C$36),"",$B39/$C$36),0) -> 0 | I39: =IF($B39>(SUM($C39:H39)),IF(ISERROR($B39/$C$36),"",$B39/$C$36),0) -> 0 | J39: =IF($B39>(SUM($C39:I39)),IF(ISERROR($B39/$C$36),"",$B39/$C$36),0) -> 0 | K39: =IF($B39>(SUM($C39:J39)),IF(ISERROR($B39/$C$36),"",$B39/$C$36),0) -> 0 | L39: =IF($B39>(SUM($C39:K39)),IF(ISERROR($B39/$C$36),"",$B39/$C$36),0) -> 0 | M39: =SUM(C39:L39) -> 11400
A40: =A17 -> Frais d’établissement | B40: =B17 | C40: =IF(ISERROR($B40/$C$36),0,$B40/$C$36) -> 0 | D40: =IF($B40>(SUM($C40:C40)),IF(ISERROR($B40/$C$36),"",$B40/$C$36),0) -> 0 | E40: =IF($B40>(SUM($C40:D40)),IF(ISERROR($B40/$C$36),"",$B40/$C$36),0) -> 0 | F40: =IF($B40>(SUM($C40:E40)),IF(ISERROR($B40/$C$36),"",$B40/$C$36),0) -> 0 | G40: =IF($B40>(SUM($C40:F40)),IF(ISERROR($B40/$C$36),"",$B40/$C$36),0) -> 0 | H40: =IF($B40>(SUM($C40:G40)),IF(ISERROR($B40/$C$36),"",$B40/$C$36),0) -> 0 | I40: =IF($B40>(SUM($C40:H40)),IF(ISERROR($B40/$C$36),"",$B40/$C$36),0) -> 0 | J40: =IF($B40>(SUM($C40:I40)),IF(ISERROR($B40/$C$36),"",$B40/$C$36),0) -> 0 | K40: =IF($B40>(SUM($C40:J40)),IF(ISERROR($B40/$C$36),"",$B40/$C$36),0) -> 0 | L40: =IF($B40>(SUM($C40:K40)),IF(ISERROR($B40/$C$36),"",$B40/$C$36),0) -> 0 | M40: =SUM(C40:L40) -> 0
J41: =IF($B41>(SUM($C41:I41)),IF(ISERROR($B41/$C$36),"",$B41/$C$36),0) -> 0 | K41: =IF($B41>(SUM($C41:J41)),IF(ISERROR($B41/$C$36),"",$B41/$C$36),0) -> 0 | L41: =IF($B41>(SUM($C41:K41)),IF(ISERROR($B41/$C$36),"",$B41/$C$36),0) -> 0 | M41: =SUM(C41:L41) -> 0
A42: =A19 -> Logiciels, formations | B42: =B19 | C42: =IF(ISERROR($B42/$C$36),0,$B42/$C$36) -> 0 | D42: =IF($B42>(SUM($C42:C42)),IF(ISERROR($B42/$C$36),"",$B42/$C$36),0) -> 0 | E42: =IF($B42>(SUM($C42:D42)),IF(ISERROR($B42/$C$36),"",$B42/$C$36),0) -> 0 | F42: =IF($B42>(SUM($C42:E42)),IF(ISERROR($B42/$C$36),"",$B42/$C$36),0) -> 0 | G42: =IF($B42>(SUM($C42:F42)),IF(ISERROR($B42/$C$36),"",$B42/$C$36),0) -> 0 | H42: =IF($B42>(SUM($C42:G42)),IF(ISERROR($B42/$C$36),"",$B42/$C$36),0) -> 0 | I42: =IF($B42>(SUM($C42:H42)),IF(ISERROR($B42/$C$36),"",$B42/$C$36),0) -> 0 | J42: =IF($B42>(SUM($C42:I42)),IF(ISERROR($B42/$C$36),"",$B42/$C$36),0) -> 0 | K42: =IF($B42>(SUM($C42:J42)),IF(ISERROR($B42/$C$36),"",$B42/$C$36),0) -> 0 | L42: =IF($B42>(SUM($C42:K42)),IF(ISERROR($B42/$C$36),"",$B42/$C$36),0) -> 0 | M42: =SUM(C42:L42) -> 0
J43: =IF($B43>(SUM($C43:I43)),IF(ISERROR($B43/$C$36),"",$B43/$C$36),0) -> 0 | K43: =IF($B43>(SUM($C43:J43)),IF(ISERROR($B43/$C$36),"",$B43/$C$36),0) -> 0 | L43: =IF($B43>(SUM($C43:K43)),IF(ISERROR($B43/$C$36),"",$B43/$C$36),0) -> 0 | M43: =SUM(C43:L43) -> 0
...

Sheet Plan financier SUCCESS
A1: cv
K2: Investissements et financements | T2: Salaires et charges sociales | AC2: Compte de résultats prévisionnel sur 3 ans | AL2: Soldes intermédiaires de gestion | AW2: Seuil de rentabilité économique | BF2: Plan de financement à trois ans | BO2: Budget prévisionnel de trésorerie | BY2: Budget prévisionnel de trésorerie (suite)
D4: ='Données à saisir'!B6 -> Gracy Omokoso
K6: Projet : | M6: =IF(ISBLANK('Données à saisir'!$B7),"",('Données à saisir'!$B7)) -> Televerx | T6: Projet : | V6: =IF(ISBLANK('Données à saisir'!$B7),"",('Données à saisir'!$B7)) -> Televerx | AC6: Projet : | AE6: =IF(ISBLANK('Données à saisir'!$B7),"",('Données à saisir'!$B7)) -> Televerx | AL6: Projet : | AN6: =IF(ISBLANK('Données à saisir'!$B7),"",('Données à saisir'!$B7)) -> Televerx | AW6: Projet : | AY6: =IF(ISBLANK('Données à saisir'!$B7),"",('Données à saisir'!$B7)) -> Televerx | BF6: Projet : | BH6: =IF(ISBLANK('Données à saisir'!$B7),"",('Données à saisir'!$B7)) -> Televerx | BO6: Projet : | BQ6: =IF(ISBLANK('Données à saisir'!$B7),"",('Données à saisir'!$B7)) -> Televerx | BV6: Hors TVA | BY6: Projet : | CA6: =IF(ISBLANK('Données à saisir'!$B7),"",('Données à saisir'!$B7)) -> Televerx | CF6: Hors TVA
K7: Porteur de projet : | M7: =IF(ISBLANK('Données à saisir'!$B6),"",('Données à saisir'!$B6)) -> Gracy Omokoso | T7: Porteur de projet : | V7: =IF(ISBLANK('Données à saisir'!$B6),"",('Données à saisir'!$B6)) -> Gracy Omokoso | AC7: Porteur de projet : | AE7: =IF(ISBLANK('Données à saisir'!$B6),"",('Données à saisir'!$B6)) -> Gracy Omokoso | AL7: Porteur de projet : | AN7: =IF(ISBLANK('Données à saisir'!$B6),"",('Données à saisir'!$B6)) -> Gracy Omokoso | AW7: Porteur de projet : | AY7: =IF(ISBLANK('Données à saisir'!$B6),"",('Données à saisir'!$B6)) -> Gracy Omokoso | BF7: Porteur de projet : | BH7: =IF(ISBLANK('Données à saisir'!$B6),"",('Données à saisir'!$B6)) -> Gracy Omokoso | BO7: Porteur de projet : | BQ7: =IF(ISBLANK('Données à saisir'!$B6),"",('Données à saisir'!$B6)) -> Gracy Omokoso | BY7: Porteur de projet : | CA7: =IF(ISBLANK('Données à saisir'!$B6),"",('Données à saisir'!$B6)) -> Gracy Omokoso
AG8: Année 1 | AH8: Année 2 | AI8: Année 3
K9: INVESTISSEMENTS | Q9: Montant hors taxes | U9: Statut juridique : | X9: =C33 | BA9: Année 1 | BB9: Année 2 | BC9: Année 3
AC10: Produits d'exploitation | AG10: =SUM(AG11:AG12) -> 87120 | AH10: =SUM(AH11:AH12) -> 113256 | AI10: =SUM(AI11:AI12) -> 169884
AC11: Chiffre d'affaires HT vente de marchandises | AG11: ='Données à saisir'!D115 -> 87120 | AH11: =AG11+AG11*'Données à saisir'!D117 -> 113256 | AI11: =AH11+AH11*'Données à saisir'!D118 -> 169884 | AO11: Année 1 | AP11: % | AQ11: Année 2 | AR11: % | AS11: Année 3 | AT11: % | AW11: Ventes + Production réelle | BA11: =AG10 -> 87120 | BB11: =AH10 -> 113256 | BC11: =AI10 -> 169884 | BO11: Première année
K12: Immobilisations incorporelles | Q12: =SUM(Q13:Q22) -> 1250 | AC12: Chiffre d'affaires HT services | AG12: ='Données à saisir'!I115 -> 0 | AH12: =AG12+AG12*'Données à saisir'!I117 -> 0 | AI12: =AH12+AH12*'Données à saisir'!I118 -> 0 | AW12: Achats consommés | BA12: =AO15 -> 26136 | BB12: =AQ15 -> 33976.8 | BC12: =AS15 -> 50965.2 | BJ12: Année 1 | BK12: Année 2 | BL12: Année 3
K13: ='Données à saisir'!A17 -> Frais d’établissement | Q13: =IF(ISBLANK('Données à saisir'!B17),"",'Données à saisir'!B17) | X13: Année 1 | Y13: Année 2 | Z13: Année 3 | AC13: Charges d'exploitation | AG13: =AG14 -> 26136 | AH13: =AH14 -> 33976.8 | AI13: =AI14 -> 50965.2 | AL13: Chiffre d'affaires | AO13: =AG10 -> 87120 | AP13: 1 | AQ13: =AH10 -> 113256 | AR13: 1 | AS13: =AI10 -> 169884 | AT13: 1 | AW13: Total des coûts variables | BA13: =BA12 -> 26136 | BB13: =BB12 -> 33976.8 | BC13: =BC12 -> 50965.2 | BR13: Mois 1 | BS13: Mois 2 | BT13: Mois 3 | BU13: Mois 4 | BV13: Mois 5 | BY13: Mois 6 | BZ13: Mois 7 | CA13: Mois 8 | CB13: Mois 9 | CC13: Mois 10 | CD13: Mois 11 | CE13: Mois 12 | CF13: TOTAL
B14: Etude financière prévisionnelle sur 3 ans | K14: ='Données à saisir'!A18 -> Frais d’ouverture de compteurs | Q14: =IF(ISBLANK('Données à saisir'!B18),"",'Données à saisir'!B18) | AC14: Achats consommés | AG14: ='Données à saisir'!$D$123*'Plan financier SUCCESS'!AG11 -> 26136 | AH14: ='Données à saisir'!$D$123*'Plan financier SUCCESS'!AH11 -> 33976.8 | AI14: ='Données à saisir'!$D$123*'Plan financier SUCCESS'!AI11 -> 50965.2 | AL14: Ventes + production réelle | AO14: =AG10 -> 87120 | AP14: 1 | AQ14: =AH10 -> 113256 | AR14: 1 | AS14: =AI10 -> 169884 | AT14: 1 | AW14: Marge sur coûts variables | BA14: =BA11-BA13 -> 60984 | BB14: =BB11-BB13 -> 79279.2 | BC14: =BC11-BC13 -> 118918.8 | BF14: Immobilisations | BJ14: =Q12+Q23 -> 12650
K15: ='Données à saisir'!A19 -> Logiciels, formations | Q15: =IF(ISBLANK('Données à saisir'!B19),"",'Données à saisir'!B19) | T15: Rémunération du (des) dirigeants | X15: ='Données à saisir'!B136 | Y15: ='Données à saisir'!C136 | Z15: ='Données à saisir'!D136 | AL15: Achats consommés | AO15: =AG14 -> 26136 | AP15: =AO15/$AO$14 -> 0.3 | AQ15: =AH14 -> 33976.8 | AR15: =AQ15/$AQ$14 -> 0.3 | AS15: =AI14 -> 50965.2 | AT15: =AS15/$AS$14 -> 0.3 | AW15: Taux de marge sur coûts variables | BA15: =IF(ISERROR(BA14/BA11),0,BA14/BA11) -> 0.7 | BB15: =IF(ISERROR(BB14/BB11),0,BB14/BB11) -> 0.7 | BC15: =IF(ISERROR(BC14/BC11),0,BC14/BC11) -> 0.7 | BF15: Acquisition des stocks | BJ15: =BR25 | BO15: Apport personnel | BR15: =BJ19 -> 20650 | CF15: =SUM(BR15:CE15) -> 20650
K16: ='Données à saisir'!A20 -> Dépôt marque, brevet, modèle | Q16: =IF(ISBLANK('Données à saisir'!B20),"",'Données à saisir'!B20) -> 500 | U16: % augmentation | Y16: =IF(ISERROR((Y15-X15)/X15),"",(Y15-X15)/X15) | Z16: =IF(ISERROR((Z15-Y15)/Y15),"",(Z15-Y15)/Y15) | AC16: Marge brute | AG16: =AG10-AG13 -> 60984 | AH16: =AH10-AH13 -> 79279.2 | AI16: =AI10-AI13 -> 118918.8 | AL16: Marge globale | AO16: =AO14-AO15 -> 60984 | AP16: =AO16/$AO$14 -> 0.7 | AQ16: =AQ14-AQ15 -> 79279.2 | AR16: =AQ16/$AQ$14 -> 0.7 | AS16: =AS14-AS15 -> 118918.8 | AT16: =AS16/$AS$14 -> 0.7 | AW16: Coûts fixes | BA16: =SUM(AO17,AO19,AO20,AO22,AO24) -> 18960 | BB16: =SUM(AQ17,AQ19,AQ20,AQ22,AQ24) -> 2280 | BC16: =SUM(AS17,AS19,AS20,AS22,AS24) -> 2280 | BF16: Variation du Besoin en fonds de roulement | BJ16: =BA39 -> 0 | BK16: =BB39-BA39 -> 0 | BL16: =+BC39-BB39 -> 0 | BO16: Emprunts | BR16: =BJ20 -> 0 | CF16: =SUM(BR16:CE16) -> 0
K17: ='Données à saisir'!A21 -> Droits d’entrée | Q17: =IF(ISBLANK('Données à saisir'!B21),"",'Données à saisir'!B21) | T17: Charges sociales du (des) dirigeant(s) | X17: ='Données à saisir'!B137 | Y17: ='Données à saisir'!C137 | Z17: ='Données à saisir'!D137 | AC17: Charges externes | AG17: =SUM(AG18:AG33) -> 10080 | AH17: =SUM(AH18:AH33) -> 0 | AI17: =SUM(AI18:AI33) -> 0 | AL17: Charges externes | AO17: =AG17 -> 10080 | AP17: =AO17/$AO$14 -> 0.11570248 | AQ17: =AH17 -> 0 | AR17: =AQ17/$AQ$14 -> 0 | AS17: =AI17 -> 0 | AT17: =AS17/$AS$14 -> 0 | AW17: Total des charges | BA17: =BA12+BA16 -> 45096 | BB17: =BB12+BB16 -> 36256.8 | BC17: =BC12+BC16 -> 53245.2 | BF17: Remboursement d'emprunts | BJ17: =AO45 -> 0 | BK17: =AQ45 -> 0 | BL17: =AS45 -> 0 | BO17: Subventions | BR17: =BJ21 -> 0 | CF17: =SUM(BR17:CE17) -> 0
K18: ='Données à saisir'!A22 -> Achat fonds de commerce ou parts | Q18: =IF(ISBLANK('Données à saisir'!B22),"",'Données à saisir'!B22) | AC18: ='Données à saisir'!A77 -> Assurances | AG18: =IF(ISBLANK('Données à saisir'!B77),0,'Données à saisir'!B77) -> 1200 | AH18: =IF(ISBLANK('Données à saisir'!C77),0,'Données à saisir'!C77) -> 0 | AI18: =IF(ISBLANK('Données à saisir'!D77),0,'Données à saisir'!D77) -> 0 | AL18: Valeur ajoutée | AO18: =AO16-AO17 -> 50904 | AP18: =AO18/$AO$14 -> 0.58429752 | AQ18: =AQ16-AQ17 -> 79279.2 | AR18: =AQ18/$AQ$14 -> 0.7 | AS18: =AS16-AS17 -> 118918.8 | AT18: =AS18/$AS$14 -> 0.7 | AW18: Résultat courant avant impôts | BA18: =AG44 -> 42024 | BB18: =AH44 -> 76999.2 | BC18: =AI44 -> 116638.8 | BF18: Total des besoins | BJ18: =SUM(BJ14:BJ17) -> 12650 | BK18: =SUM(BK14:BK17) -> 0 | BL18: =SUM(BL14:BL17) -> 0 | BO18: Autres financements | BR18: =BJ22 | CF18: =SUM(BR18:CE18) -> 0
K19: ='Données à saisir'!A23 -> Droit au bail | Q19: =IF(ISBLANK('Données à saisir'!B23),"",'Données à saisir'!B23) -> 750 | T19: Salaires des employés | X19: ='Données à saisir'!B133 -> 6600 | Y19: ='Données à saisir'!C133 | Z19: ='Données à saisir'!D133 | AC19: ='Données à saisir'!A78 -> Téléphone, internet | AG19: =IF(ISBLANK('Données à saisir'!B78),0,'Données à saisir'!B78) -> 600 | AH19: =IF(ISBLANK('Données à saisir'!C78),0,'Données à saisir'!C78) -> 0 | AI19: =IF(ISBLANK('Données à saisir'!D78),0,'Données à saisir'!D78) -> 0 | AL19: Impôts et taxes | AO19: =AG36 -> 0 | AP19: =AO19/$AO$14 -> 0 | AQ19: =AH36 -> 0 | AR19: =AQ19/$AQ$14 -> 0 | AS19: =AI36 -> 0 | AT19: =AS19/$AS$14 -> 0 | AW19: Seuil de rentabilité (chiffre d'affaires) | BA19: =IF(ISERROR(BA16/BA15),0,BA16/BA15) -> 27085.714 | BB19: =IF(ISERROR(BB16/BB15),0,BB16/BB15) -> 3257.1429 | BC19: =IF(ISERROR(BC16/BC15),0,BC16/BC15) -> 3257.1429 | BF19: Apport personnel | BJ19: =Q37 -> 20650 | BO19: Vente de marchandises | BR19: ='Données à saisir'!D103 -> 7260 | BS19: ='Données à saisir'!D104 -> 7260 | BT19: ='Données à saisir'!D105 -> 7260 | BU19: ='Données à saisir'!D106 -> 7260 | BV19: ='Données à saisir'!D107 -> 7260 | BY19: ='Données à saisir'!D108 -> 7260 | BZ19: ='Données à saisir'!D109 -> 7260 | CA19: ='Données à saisir'!D110 -> 7260 | CB19: ='Données à saisir'!D111 -> 7260 | CC19: ='Données à saisir'!D112 -> 7260 | CD19: ='Données à saisir'!D113 -> 7260 | CE19: ='Données à saisir'!D114 -> 7260 | CF19: =SUM(BR19:CE19) -> 87120
K20: ='Données à saisir'!A24 -> Caution ou dépôt de garantie | Q20: =IF(ISBLANK('Données à saisir'!B24),"",'Données à saisir'!B24) | U20: % augmentation | Y20: =IF(ISERROR((Y19-X19)/X19),"",(Y19-X19)/X19) -> -1 | Z20: =IF(ISERROR((Z19-Y19)/Y19),"",(Z19-Y19)/Y19) | AC20: ='Données à saisir'!A79 -> Autres abonnements | AG20: =IF(ISBLANK('Données à saisir'!B79),0,'Données à saisir'!B79) -> 720 | AH20: =IF(ISBLANK('Données à saisir'!C79),0,'Données à saisir'!C79) -> 0 | AI20: =IF(ISBLANK('Données à saisir'!D79),0,'Données à saisir'!D79) -> 0 | AL20: Charges de personnel | AO20: =SUM(AG37:AG40) -> 6600 | AP20: =AO20/$AO$14 -> 0.075757576 | AQ20: =SUM(AH37:AH40) -> 0 | AR20: =AQ20/$AQ$14 -> 0 | AS20: =SUM(AI37:AI40) -> 0 | AT20: =AS20/$AS$14 -> 0 | AW20: Excédent / insuffisance | BA20: =BA11-BA19 -> 60034.286 | BB20: =BB11-BB19 -> 109998.86 | BC20: =BC11-BC19 -> 166626.86 | BF20: Emprunts | BJ20: =Q40 -> 0 | BO20: Vente de services | BR20: ='Données à saisir'!I103 -> 0 | BS20: ='Données à saisir'!I104 -> 0 | BT20: ='Données à saisir'!I105 -> 0 | BU20: ='Données à saisir'!I106 -> 0 | BV20: ='Données à saisir'!I107 -> 0 | BY20: ='Données à saisir'!I108 -> 0 | BZ20: ='Données à saisir'!I109 -> 0 | CA20: ='Données à saisir'!I110 -> 0 | CB20: ='Données à saisir'!I111 -> 0 | CC20: ='Données à saisir'!I112 -> 0 | CD20: ='Données à saisir'!I113 -> 0 | CE20: ='Données à saisir'!I114 -> 0 | CF20: =SUM(BR20:CE20) -> 0
K21: ='Données à saisir'!A25 -> Frais de dossier | Q21: =IF(ISBLANK('Données à saisir'!B25),"",'Données à saisir'!B25) | T21: Charges sociales employés | X21: ='Données à saisir'!B134 | Y21: ='Données à saisir'!C134 | Z21: ='Données à saisir'!D134 | AC21: ='Données à saisir'!A80 -> Carburant | AG21: =IF(ISBLANK('Données à saisir'!B80),0,'Données à saisir'!B80) -> 0 | AH21: =IF(ISBLANK('Données à saisir'!C80),0,'Données à saisir'!C80) -> 0 | AI21: =IF(ISBLANK('Données à saisir'!D80),0,'Données à saisir'!D80) -> 0 | AL21: Excédent brut d'exploitation | AO21: =AO18-AO19-AO20 -> 44304 | AP21: =AO21/$AO$14 -> 0.50853994 | AQ21: =AQ18-AQ19-AQ20 -> 79279.2 | AR21: =AQ21/$AQ$14 -> 0.7 | AS21: =AS18-AS19-AS20 -> 118918.8 | AT21: =AS21/$AS$14 -> 0.7 | AW21: Point mort en chiffre d'affaires par jour ouvré | BA21: =BA19/250 -> 108.34286 | BB21: =BB19/250 -> 13.028571 | BC21: =BC19/250 -> 13.028571 | BF21: Subventions | BJ21: =Q44+Q45 -> 0 | BO21: Chiffre d'affaires (total) | BR21: =SUM(BR19:BR20) -> 7260 | BS21: =SUM(BS19:BS20) -> 7260 | BT21: =SUM(BT19:BT20) -> 7260 | BU21: =SUM(BU19:BU20) -> 7260 | BV21: =SUM(BV19:BV20) -> 7260 | BY21: =SUM(BY19:BY20) -> 7260 | BZ21: =SUM(BZ19:BZ20) -> 7260 | CA21: =SUM(CA19:CA20) -> 7260 | CB21: =SUM(CB19:CB20) -> 7260 | CC21: =SUM(CC19:CC20) -> 7260 | CD21: =SUM(CD19:CD20) -> 7260 | CE21: =SUM(CE19:CE20) -> 7260 | CF21: =SUM(BR21:CE21) -> 87120
K22: ='Données à saisir'!A26 -> Frais de notaire ou d’avocat | Q22: =IF(ISBLANK('Données à saisir'!B26),"",'Données à saisir'!B26) | AC22: ='Données à saisir'!A81 -> Frais de déplacement et hébergement | AG22: =IF(ISBLANK('Données à saisir'!B81),0,'Données à saisir'!B81) -> 0 | AH22: =IF(ISBLANK('Données à saisir'!C81),0,'Données à saisir'!C81) -> 0 | AI22: =IF(ISBLANK('Données à saisir'!D81),0,'Données à saisir'!D81) -> 0 | AL22: Dotation aux amortissements | AO22: =AG43 -> 2280 | AP22: =AO22/$AO$14 -> 0.026170799 | AQ22: =AH43 -> 2280 | AR22: =AQ22/$AQ$14 -> 0.020131384 | AS22: =AI43 -> 2280 | AT22: =AS22/$AS$14 -> 0.013420923 | BF22: Autres financements | BJ22: =Q46 | BO22: Immobilisations incorporelles | BR22: =Q12 -> 1250 | CF22: =SUM(BR22:CE22) -> 1250
C23: =IF(ISBLANK('Données à saisir'!B6),"",('Données à saisir'!B6)) -> Gracy Omokoso | K23: Immobilisations corporelles | Q23: =SUM(Q24:Q28) -> 11400 | AC23: ='Données à saisir'!A82 -> Eau, électricité, gaz | AG23: =IF(ISBLANK('Données à saisir'!B82),0,'Données à saisir'!B82) -> 0 | AH23: =IF(ISBLANK('Données à saisir'!C82),0,'Données à saisir'!C82) -> 0 | AI23: =IF(ISBLANK('Données à saisir'!D82),0,'Données à saisir'!D82) -> 0 | AL23: Résultat d'exploitation | AO23: =AO21-AO22 -> 42024 | AP23: =AO23/$AO$14 -> 0.48236915 | AQ23: =AQ21-AQ22 -> 76999.2 | AR23: =AQ23/$AQ$14 -> 0.67986862 | AS23: =AS21-AS22 -> 116638.8 | AT23: =AS23/$AS$14 -> 0.68657908 | BF23: Capacité d'auto-financement | BJ23: =AO44 -> 44304 | BK23: =AQ44 -> 79279.2 | BL23: =AS44 -> 118918.8 | BO23: Immobilisations corporelles | BR23: =Q23 -> 11400 | CF23: =SUM(BR23:CE23) -> 11400
K24: ='Données à saisir'!A27 -> Enseigne et éléments de communication | Q24: =IF(ISBLANK('Données à saisir'!B27),"",'Données à saisir'!B27) -> 4200 | AC24: ='Données à saisir'!A83 -> Mutuelle | AG24: =IF(ISBLANK('Données à saisir'!B83),0,'Données à saisir'!B83) -> 0 | AH24: =IF(ISBLANK('Données à saisir'!C83),0,'Données à saisir'!C83) -> 0 | AI24: =IF(ISBLANK('Données à saisir'!D83),0,'Données à saisir'!D83) -> 0 | AL24: Charges financières | AO24: =AG42 -> 0 | AP24: =AO24/$AO$14 -> 0 | AQ24: =AH42 -> 0 | AR24: =AQ24/$AQ$14 -> 0 | AS24: =AI42 -> 0 | AT24: =AS24/$AS$14 -> 0 | BF24: Total des ressources | BJ24: =SUM(BJ19:BJ23) -> 64954 | BK24: =SUM(BK19:BK23) -> 79279.2 | BL24: =SUM(BL19:BL23) -> 118918.8 | BO24: Immobilisations (total) | BR24: =SUM(BR22:BR23) -> 12650 | CF24: =SUM(BR24:CE24) -> 12650
K25: ='Données à saisir'!A28 -> Achat immobilier | Q25: =IF(ISBLANK('Données à saisir'!B28),"",'Données à saisir'!B28) | T25: Détail des amortissements | AC25: ='Données à saisir'!A84 -> Fournitures diverses | AG25: =IF(ISBLANK('Données à saisir'!B84),0,'Données à saisir'!B84) -> 0 | AH25: =IF(ISBLANK('Données à saisir'!C84),0,'Données à saisir'!C84) -> 0 | AI25: =IF(ISBLANK('Données à saisir'!D84),0,'Données à saisir'!D84) -> 0 | AL25: Résultat financier | AO25: =AO24*-1 -> 0 | AP25: =AO25/$AO$14 -> 0 | AQ25: =AQ24*-1 -> 0 | AR25: =AQ25/$AQ$14 -> 0 | AS25: =AS24*-1 -> 0 | AT25: =AS25/$AS$14 -> 0 | BF25: Variation de trésorerie | BJ25: =BJ24-BJ18 -> 52304 | BK25: =BK24-BK18 -> 79279.2 | BL25: =BL24-BL18 -> 118918.8 | BO25: Acquisition des stocks | BR25: =Q30 | CF25: =SUM(BR25:CE25) -> 0
K26: ='Données à saisir'!A29 -> Travaux et aménagements | Q26: =IF(ISBLANK('Données à saisir'!B29),"",'Données à saisir'!B29) | AC26: ='Données à saisir'!A85 -> Entretien matériel et vêtements | AG26: =IF(ISBLANK('Données à saisir'!B85),0,'Données à saisir'!B85) -> 0 | AH26: =IF(ISBLANK('Données à saisir'!C85),0,'Données à saisir'!C85) -> 0 | AI26: =IF(ISBLANK('Données à saisir'!D85),0,'Données à saisir'!D85) -> 0 | AL26: Résultat courant | AO26: =AO23+AO25 -> 42024 | AP26: =AO26/$AO$14 -> 0.48236915 | AQ26: =AQ23+AQ25 -> 76999.2 | AR26: =AQ26/$AQ$14 -> 0.67986862 | AS26: =AS23+AS25 -> 116638.8 | AT26: =AS26/$AS$14 -> 0.68657908 | BF26: Solde de trésorerie | BJ26: =BJ25 -> 52304 | BK26: =BJ26+BK25 -> 131583.2 | BL26: =+BK26+BL25 -> 250502 | BO26: Échéances emprunt | BR26: =IF(ISERROR('Données à saisir'!$J$73/12),0,'Données à saisir'!$J$73/12) -> 0 | BS26: =IF(ISERROR('Données à saisir'!$J$73/12),0,'Données à saisir'!$J$73/12) -> 0 | BT26: =IF(ISERROR('Données à saisir'!$J$73/12),0,'Données à saisir'!$J$73/12) -> 0 | BU26: =IF(ISERROR('Données à saisir'!$J$73/12),0,'Données à saisir'!$J$73/12) -> 0 | BV26: =IF(ISERROR('Données à saisir'!$J$73/12),0,'Données à saisir'!$J$73/12) -> 0 | BY26: =IF(ISERROR('Données à saisir'!$J$73/12),0,'Données à saisir'!$J$73/12) -> 0 | BZ26: =IF(ISERROR('Données à saisir'!$J$73/12),0,'Données à saisir'!$J$73/12) -> 0 | CA26: =IF(ISERROR('Données à saisir'!$J$73/12),0,'Données à saisir'!$J$73/12) -> 0 | CB26: =IF(ISERROR('Données à saisir'!$J$73/12),0,'Données à saisir'!$J$73/12) -> 0 | CC26: =IF(ISERROR('Données à saisir'!$J$73/12),0,'Données à saisir'!$J$73/12) -> 0 | CD26: =IF(ISERROR('Données à saisir'!$J$73/12),0,'Données à saisir'!$J$73/12) -> 0 | CE26: =IF(ISERROR('Données à saisir'!$J$73/12),0,'Données à saisir'!$J$73/12) -> 0 | CF26: =SUM(BR26:CE26) -> 0
K27: ='Données à saisir'!A30 -> Matériel | Q27: =IF(ISBLANK('Données à saisir'!B30),"",'Données à saisir'!B30) -> 7200 | AC27: ='Données à saisir'!A86 -> Nettoyage des locaux | AG27: =IF(ISBLANK('Données à saisir'!B86),0,'Données à saisir'!B86) -> 0 | AH27: =IF(ISBLANK('Données à saisir'!C86),0,'Données à saisir'!C86) -> 0 | AI27: =IF(ISBLANK('Données à saisir'!D86),0,'Données à saisir'!D86) -> 0 | AL27: Résultat de l'exercice | AO27: =IF(ISERROR(AO26-AG45),AO26,(AO26-AG45)) -> 42024 | AP27: =AO27/$AO$14 -> 0.48236915 | AQ27: =IF(ISERROR(AQ26-AH45),AQ26,(AQ26-AH45)) -> 76999.2 | AR27: =AQ27/$AQ$14 -> 0.67986862 | AS27: =IF(ISERROR(AS26-AI45),AS26,(AS26-AI45)) -> 116638.8 | AT27: =AS27/$AS$14 -> 0.68657908 | BO27: Achats de marchandises | BR27: =BR19*'Données à saisir'!$D$123 -> 2178 | BS27: =BS19*'Données à saisir'!$D$123 -> 2178 | BT27: =BT19*'Données à saisir'!$D$123 -> 2178 | BU27: =BU19*'Données à saisir'!$D$123 -> 2178 | BV27: =BV19*'Données à saisir'!$D$123 -> 2178 | BY27: =BY19*'Données à saisir'!$D$123 -> 2178 | BZ27: =BZ19*'Données à saisir'!$D$123 -> 2178 | CA27: =CA19*'Données à saisir'!$D$123 -> 2178 | CB27: =CB19*'Données à saisir'!$D$123 -> 2178 | CC27: =CC19*'Données à saisir'!$D$123 -> 2178 | CD27: =CD19*'Données à saisir'!$D$123 -> 2178 | CE27: =CE19*'Données à saisir'!$D$123 -> 2178 | CF27: =SUM(BR27:CE27) -> 26136
C28: =IF(ISBLANK('Données à saisir'!B7),"",('Données à saisir'!B7)) -> Televerx | K28: ='Données à saisir'!A31 -> Matériel de bureau | Q28: =IF(ISBLANK('Données à saisir'!B31),"",'Données à saisir'!B31) | AC28: ='Données à saisir'!A87 -> Budget publicité et communication | AG28: =IF(ISBLANK('Données à saisir'!B87),0,'Données à saisir'!B87) -> 4200 | AH28: =IF(ISBLANK('Données à saisir'!C87),0,'Données à saisir'!C87) -> 0 | AI28: =IF(ISBLANK('Données à saisir'!D87),0,'Données à saisir'!D87) -> 0 | AL28: Capacité d'autofinancement | AO28: =AO27+AO22 -> 44304 | AP28: =AO28/$AO$14 -> 0.50853994 | AQ28: =AQ27+AQ22 -> 79279.2 | AR28: =AQ28/$AQ$14 -> 0.7 | AS28: =AS27+AS22 -> 118918.8 | AT28: =AS28/$AS$14 -> 0.7 | BF28: Rappel trésorerie début année 1 : | BI28: =Q31 -> 8000 | BO28: Charges externes | BR28: =$AG$17/12 -> 840 | BS28: =$AG$17/12 -> 840 | BT28: =$AG$17/12 -> 840 | BU28: =$AG$17/12 -> 840 | BV28: =$AG$17/12 -> 840 | BY28: =$AG$17/12 -> 840 | BZ28: =$AG$17/12 -> 840 | CA28: =$AG$17/12 -> 840 | CB28: =$AG$17/12 -> 840 | CC28: =$AG$17/12 -> 840 | CD28: =$AG$17/12 -> 840 | CE28: =$AG$17/12 -> 840 | CF28: =SUM(BR28:CE28) -> 10080
X29: Année 1 | Y29: Année 2 | Z29: Année 3 | AC29: ='Données à saisir'!A88 -> Loyer et charges locatives | AG29: =IF(ISBLANK('Données à saisir'!B88),0,'Données à saisir'!B88) -> 3360 | AH29: =IF(ISBLANK('Données à saisir'!C88),0,'Données à saisir'!C88) -> 0 | AI29: =IF(ISBLANK('Données à saisir'!D88),0,'Données à saisir'!D88) -> 0 | AW29: Besoin en fonds de roulement | BO29: =AC36 -> Impôts et taxes | BR29: =$AG36/12 -> 0 | BS29: =$AG36/12 -> 0 | BT29: =$AG36/12 -> 0 | BU29: =$AG36/12 -> 0 | BV29: =$AG36/12 -> 0 | BY29: =$AG36/12 -> 0 | BZ29: =$AG36/12 -> 0 | CA29: =$AG36/12 -> 0 | CB29: =$AG36/12 -> 0 | CC29: =$AG36/12 -> 0 | CD29: =$AG36/12 -> 0 | CE29: =$AG36/12 -> 0 | CF29: =SUM(BR29:CE29) -> 0
K30: ='Données à saisir'!A32 -> Stock de matières et produits | Q30: =IF(ISBLANK('Données à saisir'!B32),"",'Données à saisir'!B32) | AC30: ='Données à saisir'!A89 -> Expert comptable, avocats | AG30: =IF(ISBLANK('Données à saisir'!B89),0,'Données à saisir'!B89) -> 0 | AH30: =IF(ISBLANK('Données à saisir'!C89),0,'Données à saisir'!C89) -> 0 | AI30: =IF(ISBLANK('Données à saisir'!D89),0,'Données à saisir'!D89) -> 0 | BO30: =AC37 -> Salaires employés | BR30: =$AG37/12 -> 550 | BS30: =$AG37/12 -> 550 | BT30: =$AG37/12 -> 550 | BU30: =$AG37/12 -> 550 | BV30: =$AG37/12 -> 550 | BY30: =$AG37/12 -> 550 | BZ30: =$AG37/12 -> 550 | CA30: =$AG37/12 -> 550 | CB30: =$AG37/12 -> 550 | CC30: =$AG37/12 -> 550 | CD30: =$AG37/12 -> 550 | CE30: =$AG37/12 -> 550 | CF30: =SUM(BR30:CE30) -> 6600
K31: ='Données à saisir'!A33 -> Trésorerie de départ | Q31: =IF(ISBLANK('Données à saisir'!B33),"",'Données à saisir'!B33) -> 8000 | T31: Amortissements incorporels | X31: =SUM(X33:X39) -> 0 | Y31: =SUM(Y33:Y39) -> 0 | Z31: =SUM(Z33:Z39) -> 0 | AC31: =IF(ISBLANK('Données à saisir'!A93),"",'Données à saisir'!A93) -> Libellé autre charge 1 (supprimer si inutile) | AG31: =IF(ISBLANK('Données à saisir'!B93),0,'Données à saisir'!B93) -> 0 | AH31: =IF(ISBLANK('Données à saisir'!C93),0,'Données à saisir'!C93) -> 0 | AI31: =IF(ISBLANK('Données à saisir'!D93),0,'Données à saisir'!D93) -> 0 | BO31: =AC38 -> Charges sociales employés | BR31: =$AG38/12 -> 0 | BS31: =$AG38/12 -> 0 | BT31: =$AG38/12 -> 0 | BU31: =$AG38/12 -> 0 | BV31: =$AG38/12 -> 0 | BY31: =$AG38/12 -> 0 | BZ31: =$AG38/12 -> 0 | CA31: =$AG38/12 -> 0 | CB31: =$AG38/12 -> 0 | CC31: =$AG38/12 -> 0 | CD31: =$AG38/12 -> 0 | CE31: =$AG38/12 -> 0 | CF31: =SUM(BR31:CE31) -> 0
O32: TOTAL BESOINS | Q32: =+SUM(Q12,Q23,Q30:Q31) -> 20650 | AC32: =IF(ISBLANK('Données à saisir'!A94),"",'Données à saisir'!A94) -> Libellé autre charge 2 (supprimer si inutile) | AG32: =IF(ISBLANK('Données à saisir'!B94),0,'Données à saisir'!B94) -> 0 | AH32: =IF(ISBLANK('Données à saisir'!C94),0,'Données à saisir'!C94) -> 0 | AI32: =IF(ISBLANK('Données à saisir'!D94),0,'Données à saisir'!D94) -> 0 | BO32: =AC39 -> Prélèvement dirigeant(s) | BR32: =$AG39/12 -> 0 | BS32: =$AG39/12 -> 0 | BT32: =$AG39/12 -> 0 | BU32: =$AG39/12 -> 0 | BV32: =$AG39/12 -> 0 | BY32: =$AG39/12 -> 0 | BZ32: =$AG39/12 -> 0 | CA32: =$AG39/12 -> 0 | CB32: =$AG39/12 -> 0 | CC32: =$AG39/12 -> 0 | CD32: =$AG39/12 -> 0 | CE32: =$AG39/12 -> 0 | CF32: =SUM(BR32:CE32) -> 0
C33: =IF(ISBLANK('Données à saisir'!B8),"",('Données à saisir'!B8)) | T33: =K13 -> Frais d’établissement | X33: ='Données à saisir'!C40 -> 0 | Y33: ='Données à saisir'!D40 -> 0 | Z33: ='Données à saisir'!E40 -> 0 | AC33: =IF(ISBLANK('Données à saisir'!A95),"",'Données à saisir'!A95) -> Libellé autre charge 3 (supprimer si inutile) | AG33: =IF(ISBLANK('Données à saisir'!B95),0,'Données à saisir'!B95) -> 0 | AH33: =IF(ISBLANK('Données à saisir'!C95),0,'Données à saisir'!C95) -> 0 | AI33: =IF(ISBLANK('Données à saisir'!D95),0,'Données à saisir'!D95) -> 0 | AW33: Analyse clients / fournisseurs : | BO33: =AC40 -> Charges sociales dirigeant(s) | BR33: =$AG40/12 -> 0 | BS33: =$AG40/12 -> 0 | BT33: =$AG40/12 -> 0 | BU33: =$AG40/12 -> 0 | BV33: =$AG40/12 -> 0 | BY33: =$AG40/12 -> 0 | BZ33: =$AG40/12 -> 0 | CA33: =$AG40/12 -> 0 | CB33: =$AG40/12 -> 0 | CC33: =$AG40/12 -> 0 | CD33: =$AG40/12 -> 0 | CE33: =$AG40/12 -> 0 | CF33: =SUM(BR33:CE33) -> 0
K34: FINANCEMENT DES INVESTISSEMENTS | Q34: Montant hors taxes | T34: =K15 -> Logiciels, formations | X34: ='Données à saisir'!C42 -> 0 | Y34: ='Données à saisir'!D42 -> 0 | Z34: ='Données à saisir'!E42 -> 0 | AL34: Capacité d'autofinancement | AZ34: délai jours | BA34: Année 1 | BB34: Année 2 | BC34: Année 3 | BO34: Total charges de personnel | BR34: =SUM(BR30:BR33) -> 550 | BS34: =SUM(BS30:BS33) -> 550 | BT34: =SUM(BT30:BT33) -> 550 | BU34: =SUM(BU30:BU33) -> 550 | BV34: =SUM(BV30:BV33) -> 550 | BY34: =SUM(BY30:BY33) -> 550 | BZ34: =SUM(BZ30:BZ33) -> 550 | CA34: =SUM(CA30:CA33) -> 550 | CB34: =SUM(CB30:CB33) -> 550 | CC34: =SUM(CC30:CC33) -> 550 | CD34: =SUM(CD30:CD33) -> 550 | CE34: =SUM(CE30:CE33) -> 550 | CF34: =SUM(BR34:CE34) -> 6600
T35: =K17 -> Droits d’entrée | X35: ='Données à saisir'!C44 -> 0 | Y35: ='Données à saisir'!D44 -> 0 | Z35: ='Données à saisir'!E44 -> 0 | AC35: Valeur ajoutée | AG35: =AG16-AG17 -> 50904 | AH35: =AH16-AH17 -> 79279.2 | AI35: =AI16-AI17 -> 118918.8 | AW35: Besoins | BO35: =AC42 -> Frais bancaires, charges financières | BR35: =$AG42/12 -> 0 | BS35: =$AG42/12 -> 0 | BT35: =$AG42/12 -> 0 | BU35: =$AG42/12 -> 0 | BV35: =$AG42/12 -> 0 | BY35: =$AG42/12 -> 0 | BZ35: =$AG42/12 -> 0 | CA35: =$AG42/12 -> 0 | CB35: =$AG42/12 -> 0 | CC35: =$AG42/12 -> 0 | CD35: =$AG42/12 -> 0 | CE35: =$AG42/12 -> 0 | CF35: =SUM(BR35:CE35) -> 0
T36: =K21 -> Frais de dossier | X36: ='Données à saisir'!C48 -> 0 | Y36: ='Données à saisir'!D48 -> 0 | Z36: ='Données à saisir'!E48 -> 0 | AC36: Impôts et taxes | AG36: =IF(ISBLANK('Données à saisir'!B91),0,'Données à saisir'!B91) -> 0 | AH36: =IF(ISBLANK('Données à saisir'!C91),0,'Données à saisir'!C91) -> 0 | AI36: =IF(ISBLANK('Données à saisir'!D91),0,'Données à saisir'!D91) -> 0 | AW36: Volume crédit client HT | AZ36: ='Données à saisir'!D127 -> 0 | BA36: =BA11/365*$AZ36 -> 0 | BB36: =BB11/365*$AZ36 -> 0 | BC36: =BC11/365*$AZ36 -> 0 | BO36: Total des décaissements | BR36: =SUM(BR24:BR29,BR34:BR35) -> 16218 | BS36: =SUM(BS24:BS29,BS34:BS35) -> 3568 | BT36: =SUM(BT24:BT29,BT34:BT35) -> 3568 | BU36: =SUM(BU24:BU29,BU34:BU35) -> 3568 | BV36: =SUM(BV24:BV29,BV34:BV35) -> 3568 | BY36: =SUM(BY24:BY29,BY34:BY35) -> 3568 | BZ36: =SUM(BZ24:BZ29,BZ34:BZ35) -> 3568 | CA36: =SUM(CA24:CA29,CA34:CA35) -> 3568 | CB36: =SUM(CB24:CB29,CB34:CB35) -> 3568 | CC36: =SUM(CC24:CC29,CC34:CC35) -> 3568 | CD36: =SUM(CD24:CD29,CD34:CD35) -> 3568 | CE36: =SUM(CE24:CE29,CE34:CE35) -> 3568 | CF36: =SUM(BR36:CE36) -> 55466
K37: Apport personnel | Q37: =SUM(Q38:Q39) -> 20650 | T37: =K22 -> Frais de notaire ou d’avocat | X37: ='Données à saisir'!C49 -> 0 | Y37: ='Données à saisir'!D49 -> 0 | Z37: ='Données à saisir'!E49 -> 0 | AC37: Salaires employés | AG37: ='Données à saisir'!B133 -> 6600 | AH37: ='Données à saisir'!C133 | AI37: ='Données à saisir'!D133 | AW37: Ressources | BO37: Total des encaissements | BR37: =SUM(BR15:BR20) -> 27910 | BS37: =SUM(BS15:BS20) -> 7260 | BT37: =SUM(BT15:BT20) -> 7260 | BU37: =SUM(BU15:BU20) -> 7260 | BV37: =SUM(BV15:BV20) -> 7260 | BY37: =SUM(BY15:BY20) -> 7260 | BZ37: =SUM(BZ15:BZ20) -> 7260 | CA37: =SUM(CA15:CA20) -> 7260 | CB37: =SUM(CB15:CB20) -> 7260 | CC37: =SUM(CC15:CC20) -> 7260 | CD37: =SUM(CD15:CD20) -> 7260 | CE37: =SUM(CE15:CE20) -> 7260 | CF37: =SUM(BR37:CE37) -> 107770
K38: ='Données à saisir'!A59 -> Apport personnel ou familial | Q38: =IF(ISBLANK('Données à saisir'!B59),0,'Données à saisir'!B59) -> 18050 | AC38: Charges sociales employés | AG38: ='Données à saisir'!B134 | AH38: ='Données à saisir'!C134 | AI38: ='Données à saisir'!D134 | AW38: Volume dettes fournisseurs HT | AZ38: ='Données à saisir'!D128 -> 0 | BA38: =BA12/365*$AZ38 -> 0 | BB38: =BB12/365*$AZ38 -> 0 | BC38: =BC12/365*$AZ38 -> 0 | BO38: Solde précédent | BR38: 0 | BS38: =BR40 -> 11692 | BT38: =BS40 -> 15384 | BU38: =BT40 -> 19076 | BV38: =BU40 -> 22768 | BY38: =BV40 -> 26460 | BZ38: =BY40 -> 30152 | CA38: =BZ40 -> 33844 | CB38: =CA40 -> 37536 | CC38: =CB40 -> 41228 | CD38: =CC40 -> 44920 | CE38: =CD40 -> 48612
K39: ='Données à saisir'!A60 -> Apports en nature (en valeur) | Q39: =IF(ISBLANK('Données à saisir'!B60),0,'Données à saisir'!B60) -> 2600 | AC39: Prélèvement dirigeant(s) | AG39: ='Données à saisir'!B136 | AH39: ='Données à saisir'!C136 | AI39: ='Données à saisir'!D136 | AW39: Besoin en fonds de roulement | BA39: =BA36-BA38 -> 0 | BB39: =BB36-BB38 -> 0 | BC39: =BC36-BC38 -> 0 | BO39: Solde du mois | BR39: =BR37-BR36 -> 11692 | BS39: =BS37-BS36 -> 3692 | BT39: =BT37-BT36 -> 3692 | BU39: =BU37-BU36 -> 3692 | BV39: =BV37-BV36 -> 3692 | BY39: =BY37-BY36 -> 3692 | BZ39: =BZ37-BZ36 -> 3692 | CA39: =CA37-CA36 -> 3692 | CB39: =CB37-CB36 -> 3692 | CC39: =CC37-CC36 -> 3692 | CD39: =CD37-CD36 -> 3692 | CE39: =CE37-CE36 -> 3692
K40: Emprunt | N40: taux | O40: durée mois | Q40: =SUM(Q41:Q43) -> 0 | T40: Amortissements corporels | X40: =SUM(X42:X46) -> 2280 | Y40: =SUM(Y42:Y46) -> 2280 | Z40: =SUM(Z42:Z46) -> 2280 | AC40: Charges sociales dirigeant(s) | AG40: ='Données à saisir'!B137 | AH40: ='Données à saisir'!C137 | AI40: ='Données à saisir'!D137 | AO40: Année 1 | AQ40: Année 2 | AS40: Année 3 | BO40: Solde de trésorerie (cumul) | BR40: =BR39 -> 11692 | BS40: =BS38+BS39 -> 15384 | BT40: =BT38+BT39 -> 19076 | BU40: =BU38+BU39 -> 22768 | BV40: =BV38+BV39 -> 26460 | BY40: =BY38+BY39 -> 30152 | BZ40: =BZ38+BZ39 -> 33844 | CA40: =CA38+CA39 -> 37536 | CB40: =CB38+CB39 -> 41228 | CC40: =CC38+CC39 -> 44920 | CD40: =CD38+CD39 -> 48612 | CE40: =CE38+CE39 -> 52304
K41: =IF(ISBLANK('Données à saisir'!A61),"",'Données à saisir'!A61) -> Prêt n°1 (nom de la banque) | N41: =IF(ISBLANK('Données à saisir'!C61),"",'Données à saisir'!C61) | O41: =IF(ISBLANK('Données à saisir'!D61),"",'Données à saisir'!D61) | Q41: =IF(ISBLANK('Données à saisir'!B61),0,'Données à saisir'!B61) -> 0 | AC41: Excédent brut d'exploitation | AG41: =AG35-SUM(AG36:AG40) -> 44304 | AH41: =AH35-SUM(AH36:AH40) -> 79279.2 | AI41: =AI35-SUM(AI36:AI40) -> 118918.8 | BR41: =IF(BR40<0,BR40,"") | BS41: =IF(BS40<0,BS40,"") | BT41: =IF(BT40<0,BT40,"") | BU41: =IF(BU40<0,BU40,"") | BV41: =IF(BV40<0,BV40,"") | BW41: =IF(BW40<0,BW40,"") | BX41: =IF(BX40<0,BX40,"") | BY41: =IF(BY40<0,BY40,"") | ... CE41: =IF(CE40<0,CE40,"") | CF41: =SUM(BR41:CE41) -> 0
C42: =IF(ISBLANK('Données à saisir'!B9),"",('Données à saisir'!B9)) -> +243896120025 | K42: =IF(ISBLANK('Données à saisir'!A62),"",'Données à saisir'!A62) -> Prêt n°2 (nom de la banque) | N42: =IF(ISBLANK('Données à saisir'!C62),"",'Données à saisir'!C62) | O42: =IF(ISBLANK('Données à saisir'!D62),"",'Données à saisir'!D62) | Q42: =IF(ISBLANK('Données à saisir'!B62),0,'Données à saisir'!B62) -> 0 | T42: =K24 -> Enseigne et éléments de communication | X42: ='Données à saisir'!C50 -> 840 | Y42: ='Données à saisir'!D50 -> 840 | Z42: ='Données à saisir'!E50 -> 840 | AC42: Frais bancaires, charges financières | AG42: =IF(ISERROR('Données à saisir'!B90+SUM('Données à saisir'!G70:G72)),0,'Données à saisir'!B90+SUM('Données à saisir'!G70:G72)) -> 0 | AH42: ='Données à saisir'!C90+SUM('Données à saisir'!H70:H72) -> 0 | AI42: ='Données à saisir'!D90+SUM('Données à saisir'!I70:I72) -> 0 | AL42: Résultat de l'exercice | AO42: =AO27 -> 42024 | AQ42: =AQ27 -> 76999.2 | AS42: =AS27 -> 116638.8
...

Sheet Besoin
A1: Designation | B1: Qte | C1: PU | D1: PT
A2: Immobilier
A3: Location bureau | B3: 6 | C3: 250 | D3: =B3*C3 -> 1500
A4: Ordianteur | B4: 6 | C4: 150 | D4: =B4*C4 -> 900
A5: Imprimante | B5: 1 | C5: 300 | D5: =B5*C5 -> 300
A6: Formalisation | B6: 1 | C6: 400 | D6: =B6*C6 -> 400
D7: =B7*C7 -> 0
A8: Produits et services
D9: =B9*C9 -> 0
D10: =B10*C10 -> 0
D11: =B11*C11 -> 0
D12: =B12*C12 -> 0
D13: =B13*C13 -> 0
D14: =B14*C14 -> 0
D15: =B15*C15 -> 0
D16: =B16*C16 -> 0
D17: =B17*C17 -> 0
D18: =B18*C18 -> 0
D19: =B19*C19 -> 0
D20: =B20*C20 -> 0
... D24: =B24*C24 -> 0
